Workbook

Sheet Summary
A1: QA Cross-Check: old-pipeline QA values vs newly designed models
A2: Source: QA_sheet_apeak.xlsx (QA of the old logic). New values: fable-fabulous-outcome models, computed read-only in BigQuery at the exact QA scopes. GA4 UI numbers ignored as instructed.
A4: Scoreboard (vs Old Gold Mart values)
A5: QA Tab | B5: Scope | C5: Metrics compared | D5: Match | E5: Differ (all explained)
A6: Weekly | B6: Week 18-24 May (revenue rows: 16-22 Mar) | C6: =COUNTIF('Weekly'!G:G,"MATCH")+COUNTIF('Weekly'!G:G,"DIFF") | D6: =COUNTIF('Weekly'!G:G,"MATCH") | E6: =COUNTIF('Weekly'!G:G,"DIFF")
A7: City Working | B7: Ahmedabad May; (not set) March | C7: =COUNTIF('City Working'!G:G,"MATCH")+COUNTIF('City Working'!G:G,"DIFF") | D7: =COUNTIF('City Working'!G:G,"MATCH") | E7: =COUNTIF('City Working'!G:G,"DIFF")
A8: Devices | B8: Desktop / Mobile / Total, May | C8: =COUNTIF('Devices'!G:G,"MATCH")+COUNTIF('Devices'!G:G,"DIFF") | D8: =COUNTIF('Devices'!G:G,"MATCH") | E8: =COUNTIF('Devices'!G:G,"DIFF")
A9: Prod Working | B9: SKU_102 & SKU_103, March | C9: =COUNTIF('Prod Working'!G:G,"MATCH")+COUNTIF('Prod Working'!G:G,"DIFF") | D9: =COUNTIF('Prod Working'!G:G,"MATCH") | E9: =COUNTIF('Prod Working'!G:G,"DIFF")
A10: Channel | B10: Direct / Referral / Organic / Unassigned, May | C10: =COUNTIF('Channel'!G:G,"MATCH")+COUNTIF('Channel'!G:G,"DIFF") | D10: =COUNTIF('Channel'!G:G,"MATCH") | E10: =COUNTIF('Channel'!G:G,"DIFF")
A11: Total | C11: =SUM(C6:C10) | D11: =SUM(D6:D10) | E11: =SUM(E6:E10)
A13: Findings
A14: Orders, quantity and revenue now reconcile with the raw tables and the old gold values everywhere.
A15: Counting convention: orders = distinct transaction ids among the period's purchase events, revenue/quantity = the sums those events reported. That is how GA4's own reports and the raw QA queries count, so gold reconciles with both by construction. The duplicate-id defects this property carries (re-fired ids, one id with two payloads) no longer change any number - they surface in the assert_transaction_revenue_consistency quality check instead, where the team can see and chase them.
A16: Remaining differences are deliberate and few:
A17: 1. Flag-method bounce (7 rows): the old read missed int-typed session_engaged values (1,939 events), inflating bounce. The new figure recovers them; City B's impossible 101.56% becomes a clean 100%.
A18: 2. Session attribution (5 rows): sessions are built whole and assigned to one period/city/device. Old per-window rebuilding double-counted (Desktop 934 + Mobile 31 = 965 vs their own 949 total) and clipped sessions at month edges (the small 3-condition bounce deltas). New rows sum exactly to totals.
A19: 3. Weekly New Visitors (1 row vs raw only): the raw query counted 189 first_visit events; one user fired it twice - 188 distinct new users, which both the old and new gold report.
A20: Reading the tabs: green = matches old gold to 2 decimals; amber = differs, with the explanation in the last column. QA cells stored as fractions (e.g. 0.378) were normalised to percent before comparing; each such row says so in its note.

Sheet Weekly
A1: Weekly - QA cross-check (old logic vs new gold_weekly_performance)
A2: New model values computed in BigQuery from the fable-fabulous-outcome models (read-only, full dependency chain inlined). GA4 UI column ignored as instructed.
A4: Metric | B4: Scope | C4: QA: Raw Events | D4: QA: Old Gold Mart | E4: New Model Value | F4: Match vs Raw | G4: Match vs Old Gold | H4: Delta (New - Old Gold) | I4: Explanation of difference
A5: 1. Audience & Traffic (users) | B5: Week 2026-05-18 to 2026-05-24
A6: New Visitors (New Users) | C6: 189 | D6: 188 | E6: 188 | F6: =IF(ROUND(E6-C6,2)=0,"MATCH","DIFF") | G6: =IF(ROUND(E6-D6,2)=0,"MATCH","DIFF") | H6: =ROUND(E6-D6,2) | I6: Matches old gold. The raw figure counted 189 first_visit events; one user fired it twice, 188 distinct new users.
A7: Returning Visitors | C7: 16 | D7: 16 | E7: 16 | F7: =IF(ROUND(E7-C7,2)=0,"MATCH","DIFF") | G7: =IF(ROUND(E7-D7,2)=0,"MATCH","DIFF") | H7: =ROUND(E7-D7,2)
A8: Total Visitors (Unique Users) | C8: 204 | D8: 204 | E8: 204 | F8: =IF(ROUND(E8-C8,2)=0,"MATCH","DIFF") | G8: =IF(ROUND(E8-D8,2)=0,"MATCH","DIFF") | H8: =ROUND(E8-D8,2)
A9: 2. Funnel: New Users | B9: Week 2026-05-18 to 2026-05-24
A10: Product View (New Users) | C10: 124 | D10: 124 | E10: 124 | F10: =IF(ROUND(E10-C10,2)=0,"MATCH","DIFF") | G10: =IF(ROUND(E10-D10,2)=0,"MATCH","DIFF") | H10: =ROUND(E10-D10,2)
A11: Add to Wishlist (New Users) | C11: 2 | D11: 2 | E11: 2 | F11: =IF(ROUND(E11-C11,2)=0,"MATCH","DIFF") | G11: =IF(ROUND(E11-D11,2)=0,"MATCH","DIFF") | H11: =ROUND(E11-D11,2)
A12: Add to Cart (New Users) | C12: 28 | D12: 28 | E12: 28 | F12: =IF(ROUND(E12-C12,2)=0,"MATCH","DIFF") | G12: =IF(ROUND(E12-D12,2)=0,"MATCH","DIFF") | H12: =ROUND(E12-D12,2)
A13: Orders (New Users) | C13: 4 | D13: 4 | E13: 4 | F13: =IF(ROUND(E13-C13,2)=0,"MATCH","DIFF") | G13: =IF(ROUND(E13-D13,2)=0,"MATCH","DIFF") | H13: =ROUND(E13-D13,2)
A14: Revenue Local (New Users) | B14: Week 2026-03-16 to 2026-03-22 | C14: 0 | D14: 0 | E14: 0 | F14: =IF(ROUND(E14-C14,2)=0,"MATCH","DIFF") | G14: =IF(ROUND(E14-D14,2)=0,"MATCH","DIFF") | H14: =ROUND(E14-D14,2)
A15: Revenue USD (New Users) | B15: Week 2026-03-16 to 2026-03-22 | C15: 0 | D15: 0 | E15: 0 | F15: =IF(ROUND(E15-C15,2)=0,"MATCH","DIFF") | G15: =IF(ROUND(E15-D15,2)=0,"MATCH","DIFF") | H15: =ROUND(E15-D15,2)
A16: 3. Funnel: Returning Users | B16: Week 2026-05-18 to 2026-05-24
A17: Product View (Returning) | C17: 336 | D17: 336 | E17: 336 | F17: =IF(ROUND(E17-C17,2)=0,"MATCH","DIFF") | G17: =IF(ROUND(E17-D17,2)=0,"MATCH","DIFF") | H17: =ROUND(E17-D17,2)
A18: Add to Wishlist (Returning) | C18: 0 | D18: 0 | E18: 0 | F18: =IF(ROUND(E18-C18,2)=0,"MATCH","DIFF") | G18: =IF(ROUND(E18-D18,2)=0,"MATCH","DIFF") | H18: =ROUND(E18-D18,2)
A19: Add to Cart (Returning) | C19: 55 | D19: 55 | E19: 55 | F19: =IF(ROUND(E19-C19,2)=0,"MATCH","DIFF") | G19: =IF(ROUND(E19-D19,2)=0,"MATCH","DIFF") | H19: =ROUND(E19-D19,2)
A20: Orders (Returning) | C20: 11 | D20: 11 | E20: 11 | F20: =IF(ROUND(E20-C20,2)=0,"MATCH","DIFF") | G20: =IF(ROUND(E20-D20,2)=0,"MATCH","DIFF") | H20: =ROUND(E20-D20,2)
A21: Revenue Local (Returning) | B21: Week 2026-03-16 to 2026-03-22 | C21: 4380.92 | D21: 4380.92 | E21: 4380.92 | F21: =IF(ROUND(E21-C21,2)=0,"MATCH","DIFF") | G21: =IF(ROUND(E21-D21,2)=0,"MATCH","DIFF") | H21: =ROUND(E21-D21,2)
A22: Revenue USD (Returning) | B22: Week 2026-03-16 to 2026-03-22 | C22: 4380.92 | D22: 4380.92 | E22: 4380.92 | F22: =IF(ROUND(E22-C22,2)=0,"MATCH","DIFF") | G22: =IF(ROUND(E22-D22,2)=0,"MATCH","DIFF") | H22: =ROUND(E22-D22,2)
A23: 4. Funnel: Total Users | B23: Week 2026-05-18 to 2026-05-24
A24: Product View (Total) | C24: 460 | D24: 460 | E24: 460 | F24: =IF(ROUND(E24-C24,2)=0,"MATCH","DIFF") | G24: =IF(ROUND(E24-D24,2)=0,"MATCH","DIFF") | H24: =ROUND(E24-D24,2)
A25: Add to Wishlist (Total) | C25: 2 | D25: 2 | E25: 2 | F25: =IF(ROUND(E25-C25,2)=0,"MATCH","DIFF") | G25: =IF(ROUND(E25-D25,2)=0,"MATCH","DIFF") | H25: =ROUND(E25-D25,2)
A26: Add to Cart (Total) | C26: 83 | D26: 83 | E26: 83 | F26: =IF(ROUND(E26-C26,2)=0,"MATCH","DIFF") | G26: =IF(ROUND(E26-D26,2)=0,"MATCH","DIFF") | H26: =ROUND(E26-D26,2)
A27: Orders (Total) | C27: 15 | D27: 15 | E27: 15 | F27: =IF(ROUND(E27-C27,2)=0,"MATCH","DIFF") | G27: =IF(ROUND(E27-D27,2)=0,"MATCH","DIFF") | H27: =ROUND(E27-D27,2)
A28: Revenue Local (Total) | B28: Week 2026-03-16 to 2026-03-22 | C28: 4380.92 | D28: 4380.92 | E28: 4380.92 | F28: =IF(ROUND(E28-C28,2)=0,"MATCH","DIFF") | G28: =IF(ROUND(E28-D28,2)=0,"MATCH","DIFF") | H28: =ROUND(E28-D28,2)
A29: Revenue USD (Total) | B29: Week 2026-03-16 to 2026-03-22 | C29: 4380.92 | D29: 4380.92 | E29: 4380.92 | F29: =IF(ROUND(E29-C29,2)=0,"MATCH","DIFF") | G29: =IF(ROUND(E29-D29,2)=0,"MATCH","DIFF") | H29: =ROUND(E29-D29,2)

Sheet City Working
A1: City Working - QA cross-check (old logic vs new gold_city_performance)
A2: New model values computed in BigQuery from the fable-fabulous-outcome models (read-only, full dependency chain inlined). GA4 UI column ignored as instructed.
A4: Metric | B4: Scope | C4: QA: Raw Events | D4: QA: Old Gold Mart | E4: New Model Value | F4: Match vs Raw | G4: Match vs Old Gold | H4: Delta (New - Old Gold) | I4: Explanation of difference
A5: 1. City A: Ahmedabad (Gujarat, India) | B5: Month: May 2026
A6: Visits (Sessions) | C6: 929 | D6: 929 | E6: 928 | F6: =IF(ROUND(E6-C6,2)=0,"MATCH","DIFF") | G6: =IF(ROUND(E6-D6,2)=0,"MATCH","DIFF") | H6: =ROUND(E6-D6,2) | I6: One session carried two cities; the new model assigns every session to exactly one city so city rows sum to the month total. Old event-window counting booked it under both cities.
A7: Users | C7: 453 | D7: 453 | E7: 453 | F7: =IF(ROUND(E7-C7,2)=0,"MATCH","DIFF") | G7: =IF(ROUND(E7-D7,2)=0,"MATCH","DIFF") | H7: =ROUND(E7-D7,2)
A8: Product Detail Views | C8: 1294 | D8: 1294 | E8: 1294 | F8: =IF(ROUND(E8-C8,2)=0,"MATCH","DIFF") | G8: =IF(ROUND(E8-D8,2)=0,"MATCH","DIFF") | H8: =ROUND(E8-D8,2)
A9: Add to Wishlist | C9: 17 | D9: 17 | E9: 17 | F9: =IF(ROUND(E9-C9,2)=0,"MATCH","DIFF") | G9: =IF(ROUND(E9-D9,2)=0,"MATCH","DIFF") | H9: =ROUND(E9-D9,2)
A10: Add to Cart | C10: 249 | D10: 249 | E10: 249 | F10: =IF(ROUND(E10-C10,2)=0,"MATCH","DIFF") | G10: =IF(ROUND(E10-D10,2)=0,"MATCH","DIFF") | H10: =ROUND(E10-D10,2)
A11: Orders | C11: 40 | D11: 40 | E11: 40 | F11: =IF(ROUND(E11-C11,2)=0,"MATCH","DIFF") | G11: =IF(ROUND(E11-D11,2)=0,"MATCH","DIFF") | H11: =ROUND(E11-D11,2)
A12: Revenue Local | C12: 56.95 | D12: 56.95 | E12: 56.95 | F12: =IF(ROUND(E12-C12,2)=0,"MATCH","DIFF") | G12: =IF(ROUND(E12-D12,2)=0,"MATCH","DIFF") | H12: =ROUND(E12-D12,2)
A13: Revenue USD | C13: 56.95 | D13: 56.95 | E13: 56.95 | F13: =IF(ROUND(E13-C13,2)=0,"MATCH","DIFF") | G13: =IF(ROUND(E13-D13,2)=0,"MATCH","DIFF") | H13: =ROUND(E13-D13,2)
A14: Bounce Rate - flag (%) | C14: 26.05 | D14: 26.05 | E14: 23.81 | F14: =IF(ROUND(E14-C14,2)=0,"MATCH","DIFF") | G14: =IF(ROUND(E14-D14,2)=0,"MATCH","DIFF") | H14: =ROUND(E14-D14,2) | I14: New model reads session_engaged sent as string AND as int (1,939 events arrive int-typed); the old string-only read missed that engagement, inflating flag-method bounce. The new figure is closer to what GA4 itself measures.
A15: Bounce Rate - 3 conditions (%) | C15: 33.58 | D15: 33.58 | E15: 33.51 | F15: =IF(ROUND(E15-C15,2)=0,"MATCH","DIFF") | G15: =IF(ROUND(E15-D15,2)=0,"MATCH","DIFF") | H15: =ROUND(E15-D15,2) | I15: Sessions are evaluated whole and assigned to the period they started in; old logic rebuilt sessions from the period's event window, clipping sessions at the edges.
A16: 2. City B: (not set / Unknown) | B16: Month: March 2026
A17: Visits (Sessions) | C17: 64 | D17: 64 | E17: 64 | F17: =IF(ROUND(E17-C17,2)=0,"MATCH","DIFF") | G17: =IF(ROUND(E17-D17,2)=0,"MATCH","DIFF") | H17: =ROUND(E17-D17,2) | I17: GA4's literal "(not set)" geo folds into the Unknown bucket, mirroring the old row.
A18: Users | C18: 140 | D18: 140 | E18: 140 | F18: =IF(ROUND(E18-C18,2)=0,"MATCH","DIFF") | G18: =IF(ROUND(E18-D18,2)=0,"MATCH","DIFF") | H18: =ROUND(E18-D18,2)
A19: Product Detail Views | C19: 181 | D19: 181 | E19: 181 | F19: =IF(ROUND(E19-C19,2)=0,"MATCH","DIFF") | G19: =IF(ROUND(E19-D19,2)=0,"MATCH","DIFF") | H19: =ROUND(E19-D19,2)
A20: Add to Wishlist | C20: 0 | D20: 0 | E20: 0 | F20: =IF(ROUND(E20-C20,2)=0,"MATCH","DIFF") | G20: =IF(ROUND(E20-D20,2)=0,"MATCH","DIFF") | H20: =ROUND(E20-D20,2)
A21: Add to Cart | C21: 133 | D21: 133 | E21: 133 | F21: =IF(ROUND(E21-C21,2)=0,"MATCH","DIFF") | G21: =IF(ROUND(E21-D21,2)=0,"MATCH","DIFF") | H21: =ROUND(E21-D21,2)
A22: Orders | C22: 14 | D22: 14 | E22: 14 | F22: =IF(ROUND(E22-C22,2)=0,"MATCH","DIFF") | G22: =IF(ROUND(E22-D22,2)=0,"MATCH","DIFF") | H22: =ROUND(E22-D22,2)
A23: Revenue Local | C23: 4380.92 | D23: 4380.92 | E23: 4380.92 | F23: =IF(ROUND(E23-C23,2)=0,"MATCH","DIFF") | G23: =IF(ROUND(E23-D23,2)=0,"MATCH","DIFF") | H23: =ROUND(E23-D23,2)
A24: Revenue USD | C24: 4380.92 | D24: 4380.92 | E24: 4380.92 | F24: =IF(ROUND(E24-C24,2)=0,"MATCH","DIFF") | G24: =IF(ROUND(E24-D24,2)=0,"MATCH","DIFF") | H24: =ROUND(E24-D24,2)
A25: Bounce Rate - flag (%) | C25: 101.56 | D25: 101.56 | E25: 100 | F25: =IF(ROUND(E25-C25,2)=0,"MATCH","DIFF") | G25: =IF(ROUND(E25-D25,2)=0,"MATCH","DIFF") | H25: =ROUND(E25-D25,2) | I25: Old value exceeds 100% (numerator and denominator built on different session sets). New model computes the flag per session, so the rate is structurally capped at 100.
A26: Bounce Rate - 3 conditions (%) | C26: 3.13 | D26: 3.13 | E26: 3.13 | F26: =IF(ROUND(E26-C26,2)=0,"MATCH","DIFF") | G26: =IF(ROUND(E26-D26,2)=0,"MATCH","DIFF") | H26: =ROUND(E26-D26,2)

Sheet Devices
A1: Devices - QA cross-check (old logic vs new gold_device_performance)
A2: New model values computed in BigQuery from the fable-fabulous-outcome models (read-only, full dependency chain inlined). GA4 UI column ignored as instructed.
A4: Metric | B4: Scope | C4: QA: Raw Events | D4: QA: Old Gold Mart | E4: New Model Value | F4: Match vs Raw | G4: Match vs Old Gold | H4: Delta (New - Old Gold) | I4: Explanation of difference
A5: 1. Desktop | B5: Month: May 2026
A6: Traffic (sessions) | C6: 934 | D6: 934 | E6: 918 | F6: =IF(ROUND(E6-C6,2)=0,"MATCH","DIFF") | G6: =IF(ROUND(E6-D6,2)=0,"MATCH","DIFF") | H6: =ROUND(E6-D6,2) | I6: Old per-device session counts overlap (their Desktop 934 + Mobile 31 = 965 vs their own total 949). New model assigns one device per session: 918 + 31 = 949 exactly. Per the client workbook the new mart's "traffic" column counts users (454); sessions are kept as their own column - compared here.
A7: Product View | C7: 1300 | D7: 1300 | E7: 1300 | F7: =IF(ROUND(E7-C7,2)=0,"MATCH","DIFF") | G7: =IF(ROUND(E7-D7,2)=0,"MATCH","DIFF") | H7: =ROUND(E7-D7,2)
A8: Add to Cart | C8: 250 | D8: 250 | E8: 250 | F8: =IF(ROUND(E8-C8,2)=0,"MATCH","DIFF") | G8: =IF(ROUND(E8-D8,2)=0,"MATCH","DIFF") | H8: =ROUND(E8-D8,2)
A9: Orders | C9: 40 | D9: 40 | E9: 40 | F9: =IF(ROUND(E9-C9,2)=0,"MATCH","DIFF") | G9: =IF(ROUND(E9-D9,2)=0,"MATCH","DIFF") | H9: =ROUND(E9-D9,2)
A10: Quantity | C10: 79 | D10: 79 | E10: 79 | F10: =IF(ROUND(E10-C10,2)=0,"MATCH","DIFF") | G10: =IF(ROUND(E10-D10,2)=0,"MATCH","DIFF") | H10: =ROUND(E10-D10,2)
A11: Revenue Local | C11: 56.95 | D11: 56.95 | E11: 56.95 | F11: =IF(ROUND(E11-C11,2)=0,"MATCH","DIFF") | G11: =IF(ROUND(E11-D11,2)=0,"MATCH","DIFF") | H11: =ROUND(E11-D11,2)
A12: Revenue USD | C12: 56.95 | D12: 56.95 | E12: 56.95 | F12: =IF(ROUND(E12-C12,2)=0,"MATCH","DIFF") | G12: =IF(ROUND(E12-D12,2)=0,"MATCH","DIFF") | H12: =ROUND(E12-D12,2)
A13: Bounce Rate - flag (%) | C13: 26.12 | D13: 26.12 | E13: 24.18 | F13: =IF(ROUND(E13-C13,2)=0,"MATCH","DIFF") | G13: =IF(ROUND(E13-D13,2)=0,"MATCH","DIFF") | H13: =ROUND(E13-D13,2) | I13: New model reads session_engaged sent as string AND as int (1,939 events arrive int-typed); the old string-only read missed that engagement, inflating flag-method bounce. The new figure is closer to what GA4 itself measures.
A14: Bounce Rate - 3 conditions (%) | C14: 33.83 | D14: 33.83 | E14: 34.1 | F14: =IF(ROUND(E14-C14,2)=0,"MATCH","DIFF") | G14: =IF(ROUND(E14-D14,2)=0,"MATCH","DIFF") | H14: =ROUND(E14-D14,2) | I14: Sessions are evaluated whole and assigned to the period they started in; old logic rebuilt sessions from the period's event window, clipping sessions at the edges.
A15: 2. Mobile | B15: Month: May 2026
A16: Traffic (sessions) | C16: 31 | D16: 31 | E16: 31 | F16: =IF(ROUND(E16-C16,2)=0,"MATCH","DIFF") | G16: =IF(ROUND(E16-D16,2)=0,"MATCH","DIFF") | H16: =ROUND(E16-D16,2)
A17: Product View | C17: 4 | D17: 4 | E17: 4 | F17: =IF(ROUND(E17-C17,2)=0,"MATCH","DIFF") | G17: =IF(ROUND(E17-D17,2)=0,"MATCH","DIFF") | H17: =ROUND(E17-D17,2)
A18: Add to Cart | C18: 1 | D18: 1 | E18: 1 | F18: =IF(ROUND(E18-C18,2)=0,"MATCH","DIFF") | G18: =IF(ROUND(E18-D18,2)=0,"MATCH","DIFF") | H18: =ROUND(E18-D18,2)
A19: Orders | C19: 0 | D19: 0 | E19: 0 | F19: =IF(ROUND(E19-C19,2)=0,"MATCH","DIFF") | G19: =IF(ROUND(E19-D19,2)=0,"MATCH","DIFF") | H19: =ROUND(E19-D19,2)
A20: Quantity | C20: 0 | D20: 0 | E20: 0 | F20: =IF(ROUND(E20-C20,2)=0,"MATCH","DIFF") | G20: =IF(ROUND(E20-D20,2)=0,"MATCH","DIFF") | H20: =ROUND(E20-D20,2)
A21: Revenue Local | C21: 0 | D21: 0 | E21: 0 | F21: =IF(ROUND(E21-C21,2)=0,"MATCH","DIFF") | G21: =IF(ROUND(E21-D21,2)=0,"MATCH","DIFF") | H21: =ROUND(E21-D21,2)
A22: Revenue USD | C22: 0 | D22: 0 | E22: 0 | F22: =IF(ROUND(E22-C22,2)=0,"MATCH","DIFF") | G22: =IF(ROUND(E22-D22,2)=0,"MATCH","DIFF") | H22: =ROUND(E22-D22,2)
A23: Bounce Rate - flag (%) | C23: 16.13 | D23: 16.13 | E23: 12.9 | F23: =IF(ROUND(E23-C23,2)=0,"MATCH","DIFF") | G23: =IF(ROUND(E23-D23,2)=0,"MATCH","DIFF") | H23: =ROUND(E23-D23,2) | I23: New model reads session_engaged sent as string AND as int (1,939 events arrive int-typed); the old string-only read missed that engagement, inflating flag-method bounce. The new figure is closer to what GA4 itself measures.
A24: Bounce Rate - 3 conditions (%) | C24: 51.61 | D24: 51.61 | E24: 41.94 | F24: =IF(ROUND(E24-C24,2)=0,"MATCH","DIFF") | G24: =IF(ROUND(E24-D24,2)=0,"MATCH","DIFF") | H24: =ROUND(E24-D24,2) | I24: Small base (31 sessions, 1 session = 3.2 points). Sessions are evaluated whole and assigned to the period they started in; old logic rebuilt sessions from the period's event window, clipping sessions at the edges.
A25: 3. Total Combined | B25: Month: May 2026
A26: Traffic (sessions) | C26: 949 | D26: 949 | E26: 949 | F26: =IF(ROUND(E26-C26,2)=0,"MATCH","DIFF") | G26: =IF(ROUND(E26-D26,2)=0,"MATCH","DIFF") | H26: =ROUND(E26-D26,2)
A27: Product View | C27: 1304 | D27: 1304 | E27: 1304 | F27: =IF(ROUND(E27-C27,2)=0,"MATCH","DIFF") | G27: =IF(ROUND(E27-D27,2)=0,"MATCH","DIFF") | H27: =ROUND(E27-D27,2)
A28: Add to Cart | C28: 251 | D28: 251 | E28: 251 | F28: =IF(ROUND(E28-C28,2)=0,"MATCH","DIFF") | G28: =IF(ROUND(E28-D28,2)=0,"MATCH","DIFF") | H28: =ROUND(E28-D28,2)
A29: Orders | C29: 40 | D29: 40 | E29: 40 | F29: =IF(ROUND(E29-C29,2)=0,"MATCH","DIFF") | G29: =IF(ROUND(E29-D29,2)=0,"MATCH","DIFF") | H29: =ROUND(E29-D29,2)
A30: Quantity | C30: 79 | D30: 79 | E30: 79 | F30: =IF(ROUND(E30-C30,2)=0,"MATCH","DIFF") | G30: =IF(ROUND(E30-D30,2)=0,"MATCH","DIFF") | H30: =ROUND(E30-D30,2)
A31: Revenue Local | C31: 56.95 | D31: 56.95 | E31: 56.95 | F31: =IF(ROUND(E31-C31,2)=0,"MATCH","DIFF") | G31: =IF(ROUND(E31-D31,2)=0,"MATCH","DIFF") | H31: =ROUND(E31-D31,2)
A32: Revenue USD | C32: 56.95 | D32: 56.95 | E32: 56.95 | F32: =IF(ROUND(E32-C32,2)=0,"MATCH","DIFF") | G32: =IF(ROUND(E32-D32,2)=0,"MATCH","DIFF") | H32: =ROUND(E32-D32,2)
A33: Bounce Rate - flag (%) | C33: 26.24 | D33: 26.24 | E33: 23.81 | F33: =IF(ROUND(E33-C33,2)=0,"MATCH","DIFF") | G33: =IF(ROUND(E33-D33,2)=0,"MATCH","DIFF") | H33: =ROUND(E33-D33,2) | I33: New model reads session_engaged sent as string AND as int (1,939 events arrive int-typed); the old string-only read missed that engagement, inflating flag-method bounce. The new figure is closer to what GA4 itself measures.
A34: Bounce Rate - 3 conditions (%) | C34: 34.98 | D34: 34.98 | E34: 34.35 | F34: =IF(ROUND(E34-C34,2)=0,"MATCH","DIFF") | G34: =IF(ROUND(E34-D34,2)=0,"MATCH","DIFF") | H34: =ROUND(E34-D34,2) | I34: Sessions are evaluated whole and assigned to the period they started in; old logic rebuilt sessions from the period's event window, clipping sessions at the edges.

Sheet Prod Working
A1: Prod Working - QA cross-check (old logic vs new product models, SKU grain)
A2: New model values computed in BigQuery from the fable-fabulous-outcome models (read-only, full dependency chain inlined). GA4 UI column ignored as instructed.
A4: Metric | B4: Scope | C4: QA: Raw Events | D4: QA: Old Gold Mart | E4: New Model Value | F4: Match vs Raw | G4: Match vs Old Gold | H4: Delta (New - Old Gold) | I4: Explanation of difference
A5: Cyberpunk Hoodie (SKU_102) | B5: Month: March 2026
A6: Visits | C6: 36 | D6: 36 | E6: 36 | F6: =IF(ROUND(E6-C6,2)=0,"MATCH","DIFF") | G6: =IF(ROUND(E6-D6,2)=0,"MATCH","DIFF") | H6: =ROUND(E6-D6,2)
A7: Unique visitors | C7: 74 | D7: 74 | E7: 74 | F7: =IF(ROUND(E7-C7,2)=0,"MATCH","DIFF") | G7: =IF(ROUND(E7-D7,2)=0,"MATCH","DIFF") | H7: =ROUND(E7-D7,2)
A8: Product views | C8: 59 | D8: 59 | E8: 59 | F8: =IF(ROUND(E8-C8,2)=0,"MATCH","DIFF") | G8: =IF(ROUND(E8-D8,2)=0,"MATCH","DIFF") | H8: =ROUND(E8-D8,2)
A9: Add to wishlist | C9: 0 | D9: 0 | E9: 0 | F9: =IF(ROUND(E9-C9,2)=0,"MATCH","DIFF") | G9: =IF(ROUND(E9-D9,2)=0,"MATCH","DIFF") | H9: =ROUND(E9-D9,2)
A10: Orders | C10: 1 | D10: 1 | E10: 1 | F10: =IF(ROUND(E10-C10,2)=0,"MATCH","DIFF") | G10: =IF(ROUND(E10-D10,2)=0,"MATCH","DIFF") | H10: =ROUND(E10-D10,2)
A11: Quantity | C11: 1 | D11: 1 | E11: 1 | F11: =IF(ROUND(E11-C11,2)=0,"MATCH","DIFF") | G11: =IF(ROUND(E11-D11,2)=0,"MATCH","DIFF") | H11: =ROUND(E11-D11,2)
A12: Revenue local | C12: 65.5 | D12: 65.5 | E12: 65.5 | F12: =IF(ROUND(E12-C12,2)=0,"MATCH","DIFF") | G12: =IF(ROUND(E12-D12,2)=0,"MATCH","DIFF") | H12: =ROUND(E12-D12,2)
A13: Revenue USD | C13: 65.5 | D13: 65.5 | E13: 65.5 | F13: =IF(ROUND(E13-C13,2)=0,"MATCH","DIFF") | G13: =IF(ROUND(E13-D13,2)=0,"MATCH","DIFF") | H13: =ROUND(E13-D13,2)
A14: Bounce rate - flag (%) | C14: 100 | D14: 100 | E14: 100 | F14: =IF(ROUND(E14-C14,2)=0,"MATCH","DIFF") | G14: =IF(ROUND(E14-D14,2)=0,"MATCH","DIFF") | H14: =ROUND(E14-D14,2) | I14: QA cell shows 1.0 (fraction); normalised to percent here.
A15: Bounce rate - 3 conditions (%) | C15: 0 | D15: 0 | E15: 0 | F15: =IF(ROUND(E15-C15,2)=0,"MATCH","DIFF") | G15: =IF(ROUND(E15-D15,2)=0,"MATCH","DIFF") | H15: =ROUND(E15-D15,2)
A16: PV / visit | C16: 1.64 | D16: 1.64 | E16: 1.64 | F16: =IF(ROUND(E16-C16,2)=0,"MATCH","DIFF") | G16: =IF(ROUND(E16-D16,2)=0,"MATCH","DIFF") | H16: =ROUND(E16-D16,2)
A17: AC vs PV % | C17: 103.39 | D17: 103.39 | E17: 103.39 | F17: =IF(ROUND(E17-C17,2)=0,"MATCH","DIFF") | G17: =IF(ROUND(E17-D17,2)=0,"MATCH","DIFF") | H17: =ROUND(E17-D17,2) | I17: 61 cart additions / 59 product views.
A18: Order vs Cart % | C18: 1.64 | D18: 1.64 | E18: 1.64 | F18: =IF(ROUND(E18-C18,2)=0,"MATCH","DIFF") | G18: =IF(ROUND(E18-D18,2)=0,"MATCH","DIFF") | H18: =ROUND(E18-D18,2) | I18: QA cell shows 0.0164 (fraction); normalised to percent.
A19: Conversion rate % | C19: 1.35 | D19: 1.35 | E19: 1.35 | F19: =IF(ROUND(E19-C19,2)=0,"MATCH","DIFF") | G19: =IF(ROUND(E19-D19,2)=0,"MATCH","DIFF") | H19: =ROUND(E19-D19,2) | I19: QA cell shows 0.0135 (fraction); normalised to percent.
A20: Ticket size local | C20: 65.5 | D20: 65.5 | E20: 65.5 | F20: =IF(ROUND(E20-C20,2)=0,"MATCH","DIFF") | G20: =IF(ROUND(E20-D20,2)=0,"MATCH","DIFF") | H20: =ROUND(E20-D20,2)
A21: Ticket size USD | C21: 65.5 | D21: 65.5 | E21: 65.5 | F21: =IF(ROUND(E21-C21,2)=0,"MATCH","DIFF") | G21: =IF(ROUND(E21-D21,2)=0,"MATCH","DIFF") | H21: =ROUND(E21-D21,2)
A22: AUV (revenue / quantity) | C22: 65.5 | D22: 65.5 | E22: 65.5 | F22: =IF(ROUND(E22-C22,2)=0,"MATCH","DIFF") | G22: =IF(ROUND(E22-D22,2)=0,"MATCH","DIFF") | H22: =ROUND(E22-D22,2) | I22: Matches on the old definition (revenue per unit). Per the Damas client workbook the new mart's auv column means average unique visitors per day instead.
A23: Anti-Grav Boots (SKU_103) | B23: Month: March 2026
A24: Visits | C24: 31 | D24: 31 | E24: 31 | F24: =IF(ROUND(E24-C24,2)=0,"MATCH","DIFF") | G24: =IF(ROUND(E24-D24,2)=0,"MATCH","DIFF") | H24: =ROUND(E24-D24,2)
A25: Unique visitors | C25: 66 | D25: 66 | E25: 66 | F25: =IF(ROUND(E25-C25,2)=0,"MATCH","DIFF") | G25: =IF(ROUND(E25-D25,2)=0,"MATCH","DIFF") | H25: =ROUND(E25-D25,2)
A26: Product views | C26: 42 | D26: 42 | E26: 42 | F26: =IF(ROUND(E26-C26,2)=0,"MATCH","DIFF") | G26: =IF(ROUND(E26-D26,2)=0,"MATCH","DIFF") | H26: =ROUND(E26-D26,2)
A27: Add to wishlist | C27: 0 | D27: 0 | E27: 0 | F27: =IF(ROUND(E27-C27,2)=0,"MATCH","DIFF") | G27: =IF(ROUND(E27-D27,2)=0,"MATCH","DIFF") | H27: =ROUND(E27-D27,2)
A28: Orders | C28: 10 | D28: 10 | E28: 10 | F28: =IF(ROUND(E28-C28,2)=0,"MATCH","DIFF") | G28: =IF(ROUND(E28-D28,2)=0,"MATCH","DIFF") | H28: =ROUND(E28-D28,2)
A29: Quantity | C29: 10 | D29: 10 | E29: 10 | F29: =IF(ROUND(E29-C29,2)=0,"MATCH","DIFF") | G29: =IF(ROUND(E29-D29,2)=0,"MATCH","DIFF") | H29: =ROUND(E29-D29,2)
A30: Revenue local | C30: 1200 | D30: 1200 | E30: 1200 | F30: =IF(ROUND(E30-C30,2)=0,"MATCH","DIFF") | G30: =IF(ROUND(E30-D30,2)=0,"MATCH","DIFF") | H30: =ROUND(E30-D30,2)
A31: Revenue USD | C31: 1200 | D31: 1200 | E31: 1200 | F31: =IF(ROUND(E31-C31,2)=0,"MATCH","DIFF") | G31: =IF(ROUND(E31-D31,2)=0,"MATCH","DIFF") | H31: =ROUND(E31-D31,2)
A32: Bounce rate - flag (%) | C32: 100 | D32: 100 | E32: 100 | F32: =IF(ROUND(E32-C32,2)=0,"MATCH","DIFF") | G32: =IF(ROUND(E32-D32,2)=0,"MATCH","DIFF") | H32: =ROUND(E32-D32,2)
A33: Bounce rate - 3 conditions (%) | C33: 0 | D33: 0 | E33: 0 | F33: =IF(ROUND(E33-C33,2)=0,"MATCH","DIFF") | G33: =IF(ROUND(E33-D33,2)=0,"MATCH","DIFF") | H33: =ROUND(E33-D33,2)
A34: PV / visit | C34: 1.35 | D34: 1.35 | E34: 1.35 | F34: =IF(ROUND(E34-C34,2)=0,"MATCH","DIFF") | G34: =IF(ROUND(E34-D34,2)=0,"MATCH","DIFF") | H34: =ROUND(E34-D34,2)
A35: AC vs PV % | C35: 76.19 | D35: 76.19 | E35: 76.19 | F35: =IF(ROUND(E35-C35,2)=0,"MATCH","DIFF") | G35: =IF(ROUND(E35-D35,2)=0,"MATCH","DIFF") | H35: =ROUND(E35-D35,2) | I35: 32 cart additions / 42 product views.
A36: Order vs Cart % | C36: 31.25 | D36: 31.25 | E36: 31.25 | F36: =IF(ROUND(E36-C36,2)=0,"MATCH","DIFF") | G36: =IF(ROUND(E36-D36,2)=0,"MATCH","DIFF") | H36: =ROUND(E36-D36,2)
A37: Conversion rate % | C37: 15.15 | D37: 15.15 | E37: 15.15 | F37: =IF(ROUND(E37-C37,2)=0,"MATCH","DIFF") | G37: =IF(ROUND(E37-D37,2)=0,"MATCH","DIFF") | H37: =ROUND(E37-D37,2)
A38: Ticket size local | C38: 120 | D38: 120 | E38: 120 | F38: =IF(ROUND(E38-C38,2)=0,"MATCH","DIFF") | G38: =IF(ROUND(E38-D38,2)=0,"MATCH","DIFF") | H38: =ROUND(E38-D38,2)
A39: Ticket size USD | C39: 120 | D39: 120 | E39: 120 | F39: =IF(ROUND(E39-C39,2)=0,"MATCH","DIFF") | G39: =IF(ROUND(E39-D39,2)=0,"MATCH","DIFF") | H39: =ROUND(E39-D39,2)
A40: AUV (revenue / quantity) | C40: 120 | D40: 120 | E40: 120 | F40: =IF(ROUND(E40-C40,2)=0,"MATCH","DIFF") | G40: =IF(ROUND(E40-D40,2)=0,"MATCH","DIFF") | H40: =ROUND(E40-D40,2) | I40: Same AUV definition note as the hoodie.

Sheet Channel
A1: Channel - QA cross-check (old logic vs new gold_channel_performance)
A2: New model values computed in BigQuery from the fable-fabulous-outcome models (read-only, full dependency chain inlined). GA4 UI column ignored as instructed.
A4: Metric | B4: Scope | C4: QA: Raw Events | D4: QA: Old Gold Mart | E4: New Model Value | F4: Match vs Raw | G4: Match vs Old Gold | H4: Delta (New - Old Gold) | I4: Explanation of difference
A5: 1. Channel: Direct | B5: Month: May 2026
A6: Visits (Sessions) | C6: 717 | D6: 717 | E6: 717 | F6: =IF(ROUND(E6-C6,2)=0,"MATCH","DIFF") | G6: =IF(ROUND(E6-D6,2)=0,"MATCH","DIFF") | H6: =ROUND(E6-D6,2)
A7: Unique Visitors (Users) | C7: 459 | D7: 459 | E7: 459 | F7: =IF(ROUND(E7-C7,2)=0,"MATCH","DIFF") | G7: =IF(ROUND(E7-D7,2)=0,"MATCH","DIFF") | H7: =ROUND(E7-D7,2)
A8: Average Time on Site (sec) | C8: 552.39 | D8: 552.39 | E8: 552.39 | F8: =IF(ROUND(E8-C8,2)=0,"MATCH","DIFF") | G8: =IF(ROUND(E8-D8,2)=0,"MATCH","DIFF") | H8: =ROUND(E8-D8,2)
A9: Bounce Rate - 3 conditions (%) | C9: 37.8 | D9: 37.8 | E9: 37.8 | F9: =IF(ROUND(E9-C9,2)=0,"MATCH","DIFF") | G9: =IF(ROUND(E9-D9,2)=0,"MATCH","DIFF") | H9: =ROUND(E9-D9,2) | I9: QA stores 0.378 (fraction); normalised to percent.
A10: Bounce Rate - flag (%) | C10: 28.45 | D10: 28.45 | E10: 26.5 | F10: =IF(ROUND(E10-C10,2)=0,"MATCH","DIFF") | G10: =IF(ROUND(E10-D10,2)=0,"MATCH","DIFF") | H10: =ROUND(E10-D10,2) | I10: New model reads session_engaged sent as string AND as int (1,939 events arrive int-typed); the old string-only read missed that engagement, inflating flag-method bounce. The new figure is closer to what GA4 itself measures.
A11: Product Views | C11: 768 | D11: 768 | E11: 768 | F11: =IF(ROUND(E11-C11,2)=0,"MATCH","DIFF") | G11: =IF(ROUND(E11-D11,2)=0,"MATCH","DIFF") | H11: =ROUND(E11-D11,2)
A12: Cart Additions | C12: 167 | D12: 167 | E12: 167 | F12: =IF(ROUND(E12-C12,2)=0,"MATCH","DIFF") | G12: =IF(ROUND(E12-D12,2)=0,"MATCH","DIFF") | H12: =ROUND(E12-D12,2)
A13: Orders | C13: 25 | D13: 25 | E13: 25 | F13: =IF(ROUND(E13-C13,2)=0,"MATCH","DIFF") | G13: =IF(ROUND(E13-D13,2)=0,"MATCH","DIFF") | H13: =ROUND(E13-D13,2)
A14: Revenue Local | C14: 56.95 | D14: 56.95 | E14: 56.95 | F14: =IF(ROUND(E14-C14,2)=0,"MATCH","DIFF") | G14: =IF(ROUND(E14-D14,2)=0,"MATCH","DIFF") | H14: =ROUND(E14-D14,2)
A15: Revenue USD | C15: 56.95 | D15: 56.95 | E15: 56.95 | F15: =IF(ROUND(E15-C15,2)=0,"MATCH","DIFF") | G15: =IF(ROUND(E15-D15,2)=0,"MATCH","DIFF") | H15: =ROUND(E15-D15,2)
A16: Conversion Rate % | C16: 5.45 | D16: 5.45 | E16: 5.45 | F16: =IF(ROUND(E16-C16,2)=0,"MATCH","DIFF") | G16: =IF(ROUND(E16-D16,2)=0,"MATCH","DIFF") | H16: =ROUND(E16-D16,2) | I16: New model stores 5.4466 (4 decimals); equal at 2 decimals.
A17: Traffic Contribution % | C17: 97.45 | D17: 97.45 | E17: 97.45 | F17: =IF(ROUND(E17-C17,2)=0,"MATCH","DIFF") | G17: =IF(ROUND(E17-D17,2)=0,"MATCH","DIFF") | H17: =ROUND(E17-D17,2)
A18: Order Contribution % | C18: 59.52 | D18: 59.52 | E18: 59.52 | F18: =IF(ROUND(E18-C18,2)=0,"MATCH","DIFF") | G18: =IF(ROUND(E18-D18,2)=0,"MATCH","DIFF") | H18: =ROUND(E18-D18,2)
A19: Ticket Size Local | C19: 2.28 | D19: 2.28 | E19: 2.28 | F19: =IF(ROUND(E19-C19,2)=0,"MATCH","DIFF") | G19: =IF(ROUND(E19-D19,2)=0,"MATCH","DIFF") | H19: =ROUND(E19-D19,2)
A20: Ticket Size USD | C20: 2.28 | D20: 2.28 | E20: 2.28 | F20: =IF(ROUND(E20-C20,2)=0,"MATCH","DIFF") | G20: =IF(ROUND(E20-D20,2)=0,"MATCH","DIFF") | H20: =ROUND(E20-D20,2)
A21: 2. Channel: Referral | B21: Month: May 2026
A22: Visits (Sessions) | C22: 220 | D22: 220 | E22: 220 | F22: =IF(ROUND(E22-C22,2)=0,"MATCH","DIFF") | G22: =IF(ROUND(E22-D22,2)=0,"MATCH","DIFF") | H22: =ROUND(E22-D22,2)
A23: Unique Visitors (Users) | C23: 10 | D23: 10 | E23: 10 | F23: =IF(ROUND(E23-C23,2)=0,"MATCH","DIFF") | G23: =IF(ROUND(E23-D23,2)=0,"MATCH","DIFF") | H23: =ROUND(E23-D23,2)
A24: Average Time on Site (sec) | C24: 977.91 | D24: 977.91 | E24: 977.91 | F24: =IF(ROUND(E24-C24,2)=0,"MATCH","DIFF") | G24: =IF(ROUND(E24-D24,2)=0,"MATCH","DIFF") | H24: =ROUND(E24-D24,2)
A25: Bounce Rate - 3 conditions (%) | C25: 23.18 | D25: 23.18 | E25: 23.18 | F25: =IF(ROUND(E25-C25,2)=0,"MATCH","DIFF") | G25: =IF(ROUND(E25-D25,2)=0,"MATCH","DIFF") | H25: =ROUND(E25-D25,2)
A26: Bounce Rate - flag (%) | C26: 19.09 | D26: 19.09 | E26: 15.91 | F26: =IF(ROUND(E26-C26,2)=0,"MATCH","DIFF") | G26: =IF(ROUND(E26-D26,2)=0,"MATCH","DIFF") | H26: =ROUND(E26-D26,2) | I26: New model reads session_engaged sent as string AND as int (1,939 events arrive int-typed); the old string-only read missed that engagement, inflating flag-method bounce. The new figure is closer to what GA4 itself measures.
A27: Product Views | C27: 478 | D27: 478 | E27: 478 | F27: =IF(ROUND(E27-C27,2)=0,"MATCH","DIFF") | G27: =IF(ROUND(E27-D27,2)=0,"MATCH","DIFF") | H27: =ROUND(E27-D27,2)
A28: Cart Additions | C28: 70 | D28: 70 | E28: 70 | F28: =IF(ROUND(E28-C28,2)=0,"MATCH","DIFF") | G28: =IF(ROUND(E28-D28,2)=0,"MATCH","DIFF") | H28: =ROUND(E28-D28,2)
A29: Orders | C29: 17 | D29: 17 | E29: 17 | F29: =IF(ROUND(E29-C29,2)=0,"MATCH","DIFF") | G29: =IF(ROUND(E29-D29,2)=0,"MATCH","DIFF") | H29: =ROUND(E29-D29,2)
A30: Revenue Local | C30: 0 | D30: 0 | E30: 0 | F30: =IF(ROUND(E30-C30,2)=0,"MATCH","DIFF") | G30: =IF(ROUND(E30-D30,2)=0,"MATCH","DIFF") | H30: =ROUND(E30-D30,2)
A31: Revenue USD | C31: 0 | D31: 0 | E31: 0 | F31: =IF(ROUND(E31-C31,2)=0,"MATCH","DIFF") | G31: =IF(ROUND(E31-D31,2)=0,"MATCH","DIFF") | H31: =ROUND(E31-D31,2)
A32: Conversion Rate % | C32: 170 | D32: 170 | E32: 170 | F32: =IF(ROUND(E32-C32,2)=0,"MATCH","DIFF") | G32: =IF(ROUND(E32-D32,2)=0,"MATCH","DIFF") | H32: =ROUND(E32-D32,2) | I32: QA stores 1.7 (fraction); normalised. 10 users placing 17 orders - over 100% is real on this tiny base.
A33: Traffic Contribution % | C33: 2.12 | D33: 2.12 | E33: 2.12 | F33: =IF(ROUND(E33-C33,2)=0,"MATCH","DIFF") | G33: =IF(ROUND(E33-D33,2)=0,"MATCH","DIFF") | H33: =ROUND(E33-D33,2)
A34: Order Contribution % | C34: 40.48 | D34: 40.48 | E34: 40.48 | F34: =IF(ROUND(E34-C34,2)=0,"MATCH","DIFF") | G34: =IF(ROUND(E34-D34,2)=0,"MATCH","DIFF") | H34: =ROUND(E34-D34,2)
A35: Ticket Size Local | C35: 0 | D35: 0 | E35: 0 | F35: =IF(ROUND(E35-C35,2)=0,"MATCH","DIFF") | G35: =IF(ROUND(E35-D35,2)=0,"MATCH","DIFF") | H35: =ROUND(E35-D35,2)
A36: Ticket Size USD | C36: 0 | D36: 0 | E36: 0 | F36: =IF(ROUND(E36-C36,2)=0,"MATCH","DIFF") | G36: =IF(ROUND(E36-D36,2)=0,"MATCH","DIFF") | H36: =ROUND(E36-D36,2)
A37: 3. Channel: Organic (Search) | B37: Month: May 2026
A38: Visits (Sessions) | C38: 11 | D38: 11 | E38: 11 | F38: =IF(ROUND(E38-C38,2)=0,"MATCH","DIFF") | G38: =IF(ROUND(E38-D38,2)=0,"MATCH","DIFF") | H38: =ROUND(E38-D38,2)
A39: Unique Visitors (Users) | C39: 1 | D39: 1 | E39: 1 | F39: =IF(ROUND(E39-C39,2)=0,"MATCH","DIFF") | G39: =IF(ROUND(E39-D39,2)=0,"MATCH","DIFF") | H39: =ROUND(E39-D39,2)
A40: Average Time on Site (sec) | C40: 1078.18 | D40: 1078.18 | E40: 1078.18 | F40: =IF(ROUND(E40-C40,2)=0,"MATCH","DIFF") | G40: =IF(ROUND(E40-D40,2)=0,"MATCH","DIFF") | H40: =ROUND(E40-D40,2)
A41: Bounce Rate - 3 conditions (%) | C41: 36.36 | D41: 36.36 | E41: 36.36 | F41: =IF(ROUND(E41-C41,2)=0,"MATCH","DIFF") | G41: =IF(ROUND(E41-D41,2)=0,"MATCH","DIFF") | H41: =ROUND(E41-D41,2)
...
